<?xml version="1.0"?>
<robot name="URCBOT" xmlns:xacro="http://www.ros.org/wiki/xacro">
  <xacro:property name="M_PI" value="3.1415926535897931" />
  <!--collision tags defines the body after collision-->
  <!--visual tags displays the thing....-->
  <!--inertia tags defines the physics of the body(link)-->
  <!--material tags defines the color or texture.... -->
  <!--link and joint names are self explainatory about their position-->

  <material name="Blue">
    <color rgba="0.0 0.0 0.8 1.0"/>
  </material>

  <material name="Red">
    <color rgba="0.8 0.0 0.0 1.0"/>
  </material>

  <material name="Grey2">
    <color rgba="0.9 0.9 0.9 1.0"/>
  </material>

  <material name="Black">
    <color rgba="0.1 0.1 0.1 1.0"/>
  </material>

  <material name="LightGrey">
    <color rgba="0.6 0.6 0.6 1.0"/>
  </material>


  <link name="base_link">
    <inertial>
      <origin xyz="0 0 0" rpy="0 0 0"/><!--need to check if it is the mass of COM or distri..-->
      <mass value="5"/>
      <inertia ixx="100"  ixy="0"  ixz="0" iyy="100" iyz="0" izz="100" />
    </inertial>

    <visual>
      <geometry>
        <box size="6.5 3.3 0.4"/>
      </geometry>
      <material name="Blue" ></material>
    </visual>

    <collision>
      <geometry>
        <box size="6.5 3.3 0.4"/>
      </geometry>
    </collision>

  </link>

  <!-- Hokuyo Laser -->
  <link name="hokuyo_link">
    <collision>
      <origin xyz="0 0 0" rpy="0 0 0"/>
      <geometry>
    <box size="0.1 0.1 0.1"/>
      </geometry>
    </collision>

    <visual>
      <origin xyz="0 0 0" rpy="0 0 0"/>
      <geometry>
        <mesh filename="package://simulation_2/meshes/hokuyo.dae"/>
      </geometry>
    </visual>

    <inertial>
      <mass value="1e-5" />
      <origin xyz="0 0 0" rpy="0 0 0"/>
      <inertia ixx="1e-6" ixy="0" ixz="0" iyy="1e-6" iyz="0" izz="1e-6" />
    </inertial>
  </link>

  <link name="front_right_leg">
    <inertial>
      <origin xyz="0 0 0" rpy="0 0 0"/><!--need to check if it is the mass of COM or distri..-->
      <mass value="1"/>
      <inertia ixx="100"  ixy="0"  ixz="0" iyy="100" iyz="0" izz="100" />
    </inertial>

    <visual>
      <geometry>
        <cylinder length="0.50" radius="0.6"/>
      </geometry>
      <origin rpy="1.57075 0 0" xyz="0.0 0.0 0.0"/>
      <material name="Grey2" ></material>
    </visual>

    <collision>
      <geometry>
        <cylinder length="0.50" radius="0.6"/>
      </geometry>
      <origin rpy="1.57075 0 0" xyz="0.0 0.0 0.0"/>
    </collision>
  </link>

  <link name="middle_right_leg">
    <inertial>
      <origin xyz="0 0 0" rpy="0 0 0"/><!--need to check if it is the mass of COM or distri..-->
      <mass value="1"/>
      <inertia ixx="100"  ixy="0"  ixz="0" iyy="100" iyz="0" izz="100" />
    </inertial>

    <visual>
      <geometry>
        <cylinder length="0.50" radius="0.6"/>
      </geometry>
      <origin rpy="1.57075 0 0" xyz="0.0 0.0 0.0"/>
      <material name="Grey2" ></material>
    </visual>

    <collision>
      <geometry>
        <cylinder length="0.50" radius="0.6"/>
      </geometry>
      <origin rpy="1.57075 0 0" xyz="0.0 0.0 0.0"/>
    </collision>
  </link>

  <link name="back_right_leg">
    <inertial>
      <origin xyz="0 0 0" rpy="0 0 0"/><!--need to check if it is the mass of COM or distri..-->
      <mass value="1"/>
      <inertia ixx="100"  ixy="0"  ixz="0" iyy="100" iyz="0" izz="100" />
    </inertial>

    <visual>
      <geometry>
        <cylinder length="0.50" radius="0.6"/>
      </geometry>
      <origin rpy="1.57075 0 0" xyz="0.0 0.0 0.0"/>
      <material name="Grey2" ></material>
    </visual>

    <collision>
      <geometry>
        <cylinder length="0.50" radius="0.6"/>
      </geometry>
      <origin rpy="1.57075 0 0" xyz="0.0 0.0 0.0"/>
    </collision>
  </link>

  <link name="front_left_leg">
    <inertial>
      <origin xyz="0 0 0" rpy="0 0 0"/><!--need to check if it is the mass of COM or distri..-->
      <mass value="1"/>
      <inertia ixx="100"  ixy="0"  ixz="0" iyy="100" iyz="0" izz="100" />
    </inertial>

    <visual>
      <geometry>
        <cylinder length="0.50" radius="0.6"/>
      </geometry>
      <origin rpy="1.57075 0 0" xyz="0.0 0.0 0.0"/>
      <material name="Grey2" ></material>
    </visual>

    <collision>
      <geometry>
        <cylinder length="0.50" radius="0.6"/>
      </geometry>
      <origin rpy="1.57075 0 0" xyz="0.0 0.0 0.0"/>
    </collision>
  </link>

  <link name="middle_left_leg">
    <inertial>
      <origin xyz="0 0 0" rpy="0 0 0"/><!--need to check if it is the mass of COM or distri..-->
      <mass value="1"/>
      <inertia ixx="100"  ixy="0"  ixz="0" iyy="100" iyz="0" izz="100" />
    </inertial>

    <visual>
      <geometry>
        <cylinder length="0.50" radius="0.6"/>
      </geometry>
      <origin rpy="1.57075 0 0" xyz="0.0 0.0 0.0"/>
      <material name="Grey2" ></material>
    </visual>

    <collision>
      <geometry>
        <cylinder length="0.50" radius="0.6"/>
      </geometry>
      <origin rpy="1.57075 0 0" xyz="0.0 0.0 0.0"/>
    </collision>
  </link>

  <link name="back_left_leg">
    <inertial>
      <origin xyz="0 0 0" rpy="0 0 0"/><!--need to check if it is the mass of COM or distri..-->
      <mass value="1"/>
      <inertia ixx="100"  ixy="0"  ixz="0" iyy="100" iyz="0" izz="100" />
    </inertial>

    <visual>
      <geometry>
        <cylinder length="0.50" radius="0.6"/>
      </geometry>
      <origin rpy="1.57075 0 0" xyz="0.0 0.0 0.0"/>
      <material name="Grey2" ></material>
    </visual>

    <collision>
      <geometry>
        <cylinder length="0.50" radius="0.6"/>
      </geometry>
      <origin rpy="1.57075 0 0" xyz="0.0 0.0 0.0"/>
    </collision>
  </link>

  <!--joints are like constraints used to assemble parts-->

  
  <joint name="hokuyo_joint" type="fixed">
    <axis xyz="0 1 0" />
    <origin xyz="0 0 0.65" rpy="0 0 0"/>
    <parent link="base_link"/>
    <child link="hokuyo_link"/>
  </joint>

  <joint name="base_to_front_right_leg" type="continuous">
    <axis xyz="0 1 0"/>
    <parent link="base_link"/>
    <child link="front_right_leg"/>
    <origin xyz="2.5 2.0 0.0"/>
    <calibration rising="0.0"/>
    <dynamics damping="0.0" friction="0.0"/>
    <limit effort="30" velocity="1.0" lower="-2.2" upper="0.7" />
    <safety_controller k_velocity="10" k_position="15" soft_lower_limit="-2.0" soft_upper_limit="0.5" />
  </joint>

  <joint name="base_to_back_right_leg" type="continuous">
    <axis xyz="0 1 0"/>
    <parent link="base_link"/>
    <child link="back_right_leg"/>
    <origin xyz="-2.5 2.0 0.0  "/>
    <calibration rising="0.0"/>
    <dynamics damping="0.0" friction="0.0"/>
    <limit effort="30" velocity="1.0" lower="-2.2" upper="0.7" />
    <safety_controller k_velocity="10" k_position="15" soft_lower_limit="-2.0" soft_upper_limit="0.5" />
  </joint>

  <joint name="base_to_middle_right_leg" type="continuous">
    <axis xyz="0 1 0"/>
    <parent link="base_link"/>
    <child link="middle_right_leg"/>
    <origin xyz="0 2.0 0.0 "/>
    <calibration rising="0.0"/>
    <dynamics damping="0.0" friction="0.0"/>
    <limit effort="30" velocity="1.0" lower="-2.2" upper="0.7" />
    <safety_controller k_velocity="10" k_position="15" soft_lower_limit="-2.0" soft_upper_limit="0.5" />
  </joint>

  <joint name="base_to_front_left_leg" type="continuous">
    <axis xyz="0 1 0"/>
    <parent link="base_link"/>
    <child link="front_left_leg"/>
    <origin xyz="2.5 -2.0 0.0"/>
    <calibration rising="0.0"/>
    <dynamics damping="0.0" friction="0.0"/>
    <limit effort="30" velocity="1.0" lower="-2.2" upper="0.7" />
    <safety_controller k_velocity="10" k_position="15" soft_lower_limit="-2.0" soft_upper_limit="0.5" />
  </joint>

  <joint name="base_to_back_left_leg" type="continuous">
    <axis xyz="0 1 0"/>
    <parent link="base_link"/>
    <child link="back_left_leg"/>
    <origin xyz="-2.5 -2.0 0.0  "/>
    <calibration rising="0.0"/>
    <dynamics damping="0.0" friction="0.0"/>
    <limit effort="30" velocity="1.0" lower="-2.2" upper="0.7" />
    <safety_controller k_velocity="10" k_position="15" soft_lower_limit="-2.0" soft_upper_limit="0.5" />
  </joint>

  <joint name="base_to_middle_left_leg" type="continuous">
    <axis xyz="0 1 0"/>
    <parent link="base_link"/>
    <child link="middle_left_leg"/>
    <origin xyz="0 -2.0 0.0  "/>
  </joint>


  <gazebo>
     <plugin name="diffdrive_plugin_multiwheel" filename="libdiffdrive_plugin_multi_wheel.so">
       <alwaysOn>true</alwaysOn>
       <updateRate>25.0</updateRate>
       <rightJoints>base_to_front_left_leg base_to_middle_left_leg base_to_back_left_leg</rightJoints>
       <leftJoints>base_to_front_right_leg base_to_middle_right_leg base_to_back_right_leg</leftJoints>
       <wheelSeparation>2.5</wheelSeparation>
       <wheelDiameter>1.2</wheelDiameter>
       <torque>50000</torque>
       <robotNamespace>/</robotNamespace>
       <robotBaseFrame>base_link</robotBaseFrame>
       <commandTopic>/cmd_vel</commandTopic>
       <odometryTopic>odom</odometryTopic>
       <odometryFrame>odom</odometryFrame>       
       <publishOdometryTf>1</publishOdometryTf>
       <publishOdometryMsg>1</publishOdometryMsg>
     </plugin>
  </gazebo>

  <gazebo reference="hokuyo_link">
    <sensor type="ray" name="laser">
      <pose>0 0 0 0 0 0</pose>
      <visualize>true</visualize>
      <update_rate>40</update_rate>
      <ray>
        <scan>
          <horizontal>
            <samples>720</samples>
            <resolution>1</resolution>
            <min_angle>-3.141592</min_angle>
            <max_angle>3.141592</max_angle>
          </horizontal>
        </scan>
        <range>
          <min>0.1</min>
          <max>10.0</max>
          <resolution>0.01</resolution>
        </range>
        <noise>
          <type>gaussian</type>
          <!-- Noise parameters based on published spec for Hokuyo laser
               achieving "+-30mm" accuracy at range < 10m.  A mean of 0.0m and
               stddev of 0.01m will put 99.7% of samples within 0.03m of the true
               reading. -->
          <mean>0.0</mean>
          <stddev>0.01</stddev>
        </noise>
      </ray>
      <plugin name="hokuyo_node" filename="libgazebo_ros_laser.so">
        <topicName>/scan</topicName>
        <frameName>hokuyo_link</frameName>
      </plugin>
    </sensor>
  </gazebo>
  

  <!--<gazebo reference="base_link">
    <material>Gazebo/Orange</material>
  </gazebo>

  <gazebo reference="left_wheel_1">
    <material>Gazebo/Blue</material>
  </gazebo>

  <gazebo reference="left_wheel_2">
    <material>Gazebo/Blue</material>
  </gazebo>

  <gazebo reference="left_wheel_3">
    <material>Gazebo/Blue</material>
  </gazebo>

  <gazebo reference="right_wheel_1">
    <material>Gazebo/Blue</material>
  </gazebo>

  <gazebo reference="right_wheel_2">
    <material>Gazebo/Blue</material>
  </gazebo>

  <gazebo reference="right_wheel_3">
    <material>Gazebo/Blue</material>
  </gazebo>
-->
</robot>

